[2025-03-30T21:53:37.933+0000] {local_task_job_runner.py:123} INFO - ::group::Pre task execution logs
[2025-03-30T21:53:37.995+0000] {taskinstance.py:2614} INFO - Dependencies all met for dep_context=non-requeueable deps ti=<TaskInstance: create_table_if_not_exist.create_users_table manual__2025-03-30T21:53:27.175303+00:00 [queued]>
[2025-03-30T21:53:38.029+0000] {taskinstance.py:2614} INFO - Dependencies all met for dep_context=requeueable deps ti=<TaskInstance: create_table_if_not_exist.create_users_table manual__2025-03-30T21:53:27.175303+00:00 [queued]>
[2025-03-30T21:53:38.032+0000] {taskinstance.py:2867} INFO - Starting attempt 1 of 2
[2025-03-30T21:53:38.083+0000] {taskinstance.py:2890} INFO - Executing <Task(SQLExecuteQueryOperator): create_users_table> on 2025-03-30 21:53:27.175303+00:00
[2025-03-30T21:53:38.108+0000] {warnings.py:112} WARNING - /home/***/.local/lib/python3.12/site-packages/***/task/task_runner/standard_task_runner.py:70: DeprecationWarning: This process (pid=121) is multi-threaded, use of fork() may lead to deadlocks in the child.
  pid = os.fork()

[2025-03-30T21:53:38.124+0000] {standard_task_runner.py:72} INFO - Started process 125 to run task
[2025-03-30T21:53:38.122+0000] {standard_task_runner.py:104} INFO - Running: ['***', 'tasks', 'run', 'create_table_if_not_exist', 'create_users_table', 'manual__2025-03-30T21:53:27.175303+00:00', '--job-id', '4', '--raw', '--subdir', 'DAGS_FOLDER/create_sql_tables.py', '--cfg-path', '/tmp/tmpajaqtlsn']
[2025-03-30T21:53:38.127+0000] {standard_task_runner.py:105} INFO - Job 4: Subtask create_users_table
[2025-03-30T21:53:38.373+0000] {task_command.py:467} INFO - Running <TaskInstance: create_table_if_not_exist.create_users_table manual__2025-03-30T21:53:27.175303+00:00 [running]> on host 3947a336792d
[2025-03-30T21:53:38.711+0000] {taskinstance.py:3134} INFO - Exporting env vars: AIRFLOW_CTX_DAG_OWNER='azizjon' AIRFLOW_CTX_DAG_ID='create_table_if_not_exist' AIRFLOW_CTX_TASK_ID='create_users_table' AIRFLOW_CTX_EXECUTION_DATE='2025-03-30T21:53:27.175303+00:00' AIRFLOW_CTX_TRY_NUMBER='1' AIRFLOW_CTX_DAG_RUN_ID='manual__2025-03-30T21:53:27.175303+00:00'
[2025-03-30T21:53:38.715+0000] {taskinstance.py:732} INFO - ::endgroup::
[2025-03-30T21:53:38.872+0000] {sql.py:295} INFO - Executing: 
            CREATE TABLE IF NOT EXISTS users (
                user_id INTEGER PRIMARY KEY,
                location VARCHAR(255),
                age INTEGER
            );
        
[2025-03-30T21:53:38.907+0000] {base.py:84} INFO - Retrieving connection 'postgres_localhost'
[2025-03-30T21:53:38.974+0000] {base.py:84} INFO - Retrieving connection 'postgres_localhost'
[2025-03-30T21:53:39.160+0000] {sql.py:511} INFO - Running statement: 
            CREATE TABLE IF NOT EXISTS users (
                user_id INTEGER PRIMARY KEY,
                location VARCHAR(255),
                age INTEGER
            );
        , parameters: None
[2025-03-30T21:53:39.365+0000] {taskinstance.py:3313} ERROR - Task failed with exception
Traceback (most recent call last):
  File "/home/airflow/.local/lib/python3.12/site-packages/airflow/models/taskinstance.py", line 768, in _execute_task
    result = _execute_callable(context=context, **execute_callable_kwargs)
             ^^^^^^^^^^^^^^^^^^^^^^^^^^^^^^^^^^^^^^^^^^^^^^^^^^^^^^^^^^^^^
  File "/home/airflow/.local/lib/python3.12/site-packages/airflow/models/taskinstance.py", line 734, in _execute_callable
    return ExecutionCallableRunner(
           ^^^^^^^^^^^^^^^^^^^^^^^^
  File "/home/airflow/.local/lib/python3.12/site-packages/airflow/utils/operator_helpers.py", line 252, in run
    return self.func(*args, **kwargs)
           ^^^^^^^^^^^^^^^^^^^^^^^^^^
  File "/home/airflow/.local/lib/python3.12/site-packages/airflow/models/baseoperator.py", line 424, in wrapper
    return func(self, *args, **kwargs)
           ^^^^^^^^^^^^^^^^^^^^^^^^^^^
  File "/home/airflow/.local/lib/python3.12/site-packages/airflow/providers/common/sql/operators/sql.py", line 301, in execute
    output = hook.run(
             ^^^^^^^^^
  File "/home/airflow/.local/lib/python3.12/site-packages/airflow/providers/common/sql/hooks/sql.py", line 467, in run
    self._run_command(cur, sql_statement, parameters)
  File "/home/airflow/.local/lib/python3.12/site-packages/airflow/providers/common/sql/hooks/sql.py", line 516, in _run_command
    cur.execute(sql_statement)
psycopg2.errors.UniqueViolation: duplicate key value violates unique constraint "pg_type_typname_nsp_index"
DETAIL:  Key (typname, typnamespace)=(users, 2200) already exists.

[2025-03-30T21:53:39.427+0000] {taskinstance.py:1226} INFO - Marking task as UP_FOR_RETRY. dag_id=create_table_if_not_exist, task_id=create_users_table, run_id=manual__2025-03-30T21:53:27.175303+00:00, execution_date=20250330T215327, start_date=20250330T215337, end_date=20250330T215339
[2025-03-30T21:53:39.534+0000] {taskinstance.py:341} INFO - ::group::Post task execution logs
[2025-03-30T21:53:39.542+0000] {standard_task_runner.py:124} ERROR - Failed to execute job 4 for task create_users_table (duplicate key value violates unique constraint "pg_type_typname_nsp_index"
DETAIL:  Key (typname, typnamespace)=(users, 2200) already exists.
; 125)
Traceback (most recent call last):
  File "/home/airflow/.local/lib/python3.12/site-packages/airflow/task/task_runner/standard_task_runner.py", line 117, in _start_by_fork
    ret = args.func(args, dag=self.dag)
          ^^^^^^^^^^^^^^^^^^^^^^^^^^^^^
  File "/home/airflow/.local/lib/python3.12/site-packages/airflow/cli/cli_config.py", line 49, in command
    return func(*args, **kwargs)
           ^^^^^^^^^^^^^^^^^^^^^
  File "/home/airflow/.local/lib/python3.12/site-packages/airflow/utils/cli.py", line 116, in wrapper
    return f(*args, **kwargs)
           ^^^^^^^^^^^^^^^^^^
  File "/home/airflow/.local/lib/python3.12/site-packages/airflow/cli/commands/task_command.py", line 483, in task_run
    task_return_code = _run_task_by_selected_method(args, _dag, ti)
                       ^^^^^^^^^^^^^^^^^^^^^^^^^^^^^^^^^^^^^^^^^^^^
  File "/home/airflow/.local/lib/python3.12/site-packages/airflow/cli/commands/task_command.py", line 256, in _run_task_by_selected_method
    return _run_raw_task(args, ti)
           ^^^^^^^^^^^^^^^^^^^^^^^
  File "/home/airflow/.local/lib/python3.12/site-packages/airflow/cli/commands/task_command.py", line 341, in _run_raw_task
    return ti._run_raw_task(
           ^^^^^^^^^^^^^^^^^
  File "/home/airflow/.local/lib/python3.12/site-packages/airflow/utils/session.py", line 97, in wrapper
    return func(*args, session=session, **kwargs)
           ^^^^^^^^^^^^^^^^^^^^^^^^^^^^^^^^^^^^^^
  File "/home/airflow/.local/lib/python3.12/site-packages/airflow/models/taskinstance.py", line 3006, in _run_raw_task
    return _run_raw_task(
           ^^^^^^^^^^^^^^
  File "/home/airflow/.local/lib/python3.12/site-packages/airflow/models/taskinstance.py", line 274, in _run_raw_task
    TaskInstance._execute_task_with_callbacks(
  File "/home/airflow/.local/lib/python3.12/site-packages/airflow/models/taskinstance.py", line 3161, in _execute_task_with_callbacks
    result = self._execute_task(context, task_orig)
             ^^^^^^^^^^^^^^^^^^^^^^^^^^^^^^^^^^^^^^
  File "/home/airflow/.local/lib/python3.12/site-packages/airflow/models/taskinstance.py", line 3185, in _execute_task
    return _execute_task(self, context, task_orig)
           ^^^^^^^^^^^^^^^^^^^^^^^^^^^^^^^^^^^^^^^
  File "/home/airflow/.local/lib/python3.12/site-packages/airflow/models/taskinstance.py", line 768, in _execute_task
    result = _execute_callable(context=context, **execute_callable_kwargs)
             ^^^^^^^^^^^^^^^^^^^^^^^^^^^^^^^^^^^^^^^^^^^^^^^^^^^^^^^^^^^^^
  File "/home/airflow/.local/lib/python3.12/site-packages/airflow/models/taskinstance.py", line 734, in _execute_callable
    return ExecutionCallableRunner(
           ^^^^^^^^^^^^^^^^^^^^^^^^
  File "/home/airflow/.local/lib/python3.12/site-packages/airflow/utils/operator_helpers.py", line 252, in run
    return self.func(*args, **kwargs)
           ^^^^^^^^^^^^^^^^^^^^^^^^^^
  File "/home/airflow/.local/lib/python3.12/site-packages/airflow/models/baseoperator.py", line 424, in wrapper
    return func(self, *args, **kwargs)
           ^^^^^^^^^^^^^^^^^^^^^^^^^^^
  File "/home/airflow/.local/lib/python3.12/site-packages/airflow/providers/common/sql/operators/sql.py", line 301, in execute
    output = hook.run(
             ^^^^^^^^^
  File "/home/airflow/.local/lib/python3.12/site-packages/airflow/providers/common/sql/hooks/sql.py", line 467, in run
    self._run_command(cur, sql_statement, parameters)
  File "/home/airflow/.local/lib/python3.12/site-packages/airflow/providers/common/sql/hooks/sql.py", line 516, in _run_command
    cur.execute(sql_statement)
psycopg2.errors.UniqueViolation: duplicate key value violates unique constraint "pg_type_typname_nsp_index"
DETAIL:  Key (typname, typnamespace)=(users, 2200) already exists.

[2025-03-30T21:53:39.593+0000] {local_task_job_runner.py:266} INFO - Task exited with return code 1
[2025-03-30T21:53:39.625+0000] {local_task_job_runner.py:245} INFO - ::endgroup::
